<!-- https://mujoco.readthedocs.io/en/latest/overview.html?highlight=hello.xml#examples -->
<mujoco>
  <option gravity = "0 0 -9.81" />

  <default>
    <joint frictionloss="0.3" />
    <motor ctrlrange="-2 2"/>
  </default>
  <worldbody>
    <light diffuse="0 0 0" pos="0 0 10" dir="0 0 -1"/>
    <body pos="0 0 0" euler="0 0 0">
        <joint name="joint0" type="hinge" axis = "0 -1 0" pos = "0 0 0.5" />
        <geom type="cylinder" size="0.05 0.5" rgba="1 0 0 1" mass="1"/>
    </body>
  </worldbody>
   <actuator>
     <motor name="torque0" joint="joint0"  gear="1" />
   </actuator>
</mujoco>
