<mujoco model="ufactory_lite6">
  <compiler angle="radian" meshdir="../../mujoco_menagerie/ufactory_lite6/assets" autolimits="true"/>
  <option integrator="implicitfast"/>

  <include file="realsense_d435.xml"/>
  <default>
    <default class="lite6">
      <geom type="mesh"/>
      <joint axis="0 0 1" damping="1" armature="0.1"/>

      <!-- Each actuator is defined by its size and control type (pos, vel)
      Unfortunately mujoco does not allow inheritance from two classes, and any defaults applied to one actuator type apply to others as they are all "general"
      So we can only set either defaults for motor size or actuator type via the class, not both. Here I choose to go with the class for motor size. Alternatively we could
      have more classes that are a composite of size and motor type, but it seems cleaner to just specify the gains and groups altogether in the actuator definitions
      -->
      <default class="size1">
        <general forcerange="-50 50"/>
      </default>
      <default class="size2">
        <general forcerange="-32 32"/>
      </default>
      <default class="size3">
        <general forcerange="-20 20"/>
      </default>

      <default class="visual">
        <geom contype="0" conaffinity="0" group="2" material="white"/>
        <default class="target">
          <geom type="box" size=".015"/>
        </default>
      </default>
      <default class="collision">
        <geom group="3" mass="0" density="0"/>
      </default>

    </default>
  </default>

  <asset>
    <material name="white" rgba="1 1 1 1"/>
    <material name="silver" rgba=".753 .753 .753 1"/>
    <material name="black" rgba=".1 .1 .1 1"/>

    <mesh file="visual/link_base.stl"/>
    <mesh file="visual/link1.stl"/>
    <mesh file="visual/link2.stl"/>
    <mesh file="visual/link3.stl"/>
    <mesh file="visual/link4.stl"/>
    <mesh file="visual/link5.stl"/>
    <mesh file="visual/link6.stl"/>
    <mesh file="visual/gripper_lite_body.stl"/>
    <mesh file="visual/gripper_lite_left_finger_wide.stl"/>
    <mesh file="visual/gripper_lite_right_finger_wide.stl"/>
    <mesh name="link_base_c" file="collision/link_base.stl"/>
    <mesh name="link1_c" file="collision/link1.stl"/>
    <mesh name="link2_c" file="collision/link2.stl"/>
    <mesh name="link3_c" file="collision/link3.stl"/>
    <mesh name="link4_c" file="collision/link4.stl"/>
    <mesh name="link5_c" file="collision/link5.stl"/>
    <mesh name="link6_c" file="collision/link6.stl"/>
    <mesh name="gripper_lite_body_c" file="collision/gripper_lite_body.stl"/>
    <mesh file="collision/gripper_lite_left_finger_wide_base.stl"/>
    <mesh file="collision/gripper_lite_right_finger_wide_base.stl"/>
    <mesh file="collision/gripper_lite_left_finger_wide_tip.stl"/>
    <mesh file="collision/gripper_lite_right_finger_wide_tip.stl"/>
  </asset>

  <!-- <visual>  
    <headlight diffuse="0.6 0.6 0.6" ambient="0.3 0.3 0.3" specular="0 0 0"/>
    <rgba haze="0.15 0.25 0.35 1"/>
    <global azimuth="120" elevation="-20"/>
  </visual>

  <asset>
    <texture type="skybox" builtin="gradient" rgb1="0.3 0.5 0.7" rgb2="0 0 0" width="512" height="3072"/>
    <texture type="2d" name="groundplane" builtin="checker" mark="edge" rgb1="0.2 0.3 0.4" rgb2="0.1 0.2 0.3"
      markrgb="0.8 0.8 0.8" width="300" height="300"/>
    <material name="groundplane" texture="groundplane" texuniform="true" texrepeat="5 5" reflectance="0.2"/>
  </asset> -->

  <worldbody>

    <body name="link_base" childclass="lite6">
      <inertial pos="-0.00829545 3.26357e-05 0.0631195" mass="1.65394" diaginertia="0 0 0"/>
      <!-- Angled down 25 deg -->
      <camera name="side_cam" class="realsense_d435i_rgb_640" mode="fixed" pos="1.2 0 0.4" quat="0.560985526796931 0.43045933457687946 0.4304593345768794 0.5609855267969309"/>
      <geom class="visual" mesh="link_base"/>
      <geom name="link_base_c" class="collision" mesh="link_base_c"/>
      <body name="link1" pos="0 0 0.2435">
        <inertial pos="-0.00036 0.04195 -0.0025" quat="0.608059 0.792349 -0.0438707 0.0228718" mass="1.411"
          diaginertia="0.00145276 0.00135275 0.000853355"/>
        <joint name="joint1" range="-6.28319 6.28319"/>
        <geom class="visual" mesh="link1"/>
        <geom name="link1_c" class="collision" mesh="link1_c"/>
        <body name="link2" quat="-1 1 1 1">
          <inertial pos="0.179 0 0.0584" quat="0.417561 0.571619 0.569585 0.417693" mass="1.34"
            diaginertia="0.00560971 0.0052152 0.00122018"/>
          <joint name="joint2" range="-2.61799 2.61799"/>
          <geom class="visual" mesh="link2"/>
          <geom name="link2_c" class="collision" mesh="link2_c"/>
          <body name="link3" pos="0.2002 0 0" quat="-2.59734e-06 -0.707105 -0.707108 -2.59735e-06">
            <inertial pos="0.072 -0.0357 -0.001" quat="0.128259 0.662963 -0.167256 0.71837" mass="0.953"
              diaginertia="0.0018521 0.00175546 0.000703807"/>
            <joint name="joint3" range="-0.061087 5.23599"/>
            <geom class="visual" mesh="link3"/>
            <geom name="link3_c" class="collision" mesh="link3_c"/>
            <body name="link4" pos="0.087 -0.22761 0" quat="0.707105 0.707108 0 0">
              <inertial pos="-0.002 -0.0285 -0.0813" quat="0.975248 0.22109 0.00203498 -0.00262178" mass="1.284"
                diaginertia="0.00370503 0.00349091 0.00109586"/>
              <joint name="joint4" range="-6.28319 6.28319"/>
              <geom class="visual" mesh="link4"/>
              <geom name="link4_c" class="collision" mesh="link4_c"/>
              <body name="link5" quat="1 1 0 0">
                <inertial pos="0 0.01 0.0019" quat="0.71423 0.696388 -0.0531933 0.0456997" mass="0.804"
                  diaginertia="0.000567553 0.000529266 0.000507681"/>
                <joint name="joint5" range="-2.1642 2.1642"/>
                <geom class="visual" mesh="link5"/>
                <geom name="link5_c" class="collision" mesh="link5_c"/>
                <body name="link6" pos="0 0.0625 0" quat="1 -1 0 0">
                  <inertial pos="0 -0.00194 -0.0102" quat="-0.0376023 0.704057 0.0446838 0.707738" mass="0.13"
                    diaginertia="0.000148148 8.57757e-05 7.71412e-05"/>
                  <joint name="joint6" range="-6.28319 6.28319"/>
                  <geom class="visual" mesh="link6" material="silver"/>
                  <geom name="link6_c" class="collision" mesh="link6_c"/>
                  <site name="attachment_site"/>
                  <camera name="gripper_cam" class="realsense_d435i_rgb_640" mode="fixed" pos="0.1 0 0" euler="3.141592653589793 0.7 -1.5707963267948966"/>
                  <body name="gripper_body" pos="0 0 0" quat="1 0 0 0">
                    <inertial pos="0.0 0.0 0.026" quat="1 0 0 0" mass="0.26"
                      diaginertia="0.00016117 0.000118 0.00014455" />
                    <geom class="visual" mesh="gripper_lite_body" material="white"/>
                    <geom name="gripper_lite_body_c" class="collision" mesh="gripper_lite_body_c"/>
                    <!-- Finger and base separated to avoid convex hull preventing gripping -->
                    <body name="gripper_left_finger" pos="0 0 0.054" quat="1 0 0 0">
                      <inertial pos="0.0 -0.01 0.01" quat="1 0 0 0" mass="0.024"
                        diaginertia="1.961e-6 2.274e-6 1.238e-6" />
                      <joint name="gripper_left_finger" pos="0 0 0" axis="0 1 0" type="slide" limited="true" range="-0.0081 -1e-5" frictionloss="0.4" />
                      <geom mesh="gripper_lite_left_finger_wide" class="visual" material="black"/>
                      <geom name="gripper_left_finger_base" class="collision" mesh="gripper_lite_left_finger_wide_base" material="black" condim="1" solimp="2 1 0.01" solref="0.01 1" friction="6 0.5 0.1"/>
                      <geom name="gripper_left_finger" class="collision" mesh="gripper_lite_left_finger_wide_tip" material="black" condim="4" solimp="2 1 0.01" solref="0.01 1" friction="6 0.5 0.1"/>
                    </body>
                    <body name="gripper_right_finger" pos="0 0 0.054" quat="1 0 0 0">
                      <inertial pos="0.0 0.01 0.01" quat="1 0 0 0" mass="0.024"
                        diaginertia="1.961e-6 2.274e-6 1.238e-6" />
                      <joint name="gripper_right_finger" pos="0 0 0" axis="0 1 0" type="slide" limited="true" range="1e-5 0.0081" frictionloss="0.4" />
                      <geom mesh="gripper_lite_right_finger_wide" class="visual" material="black"/>
                      <geom name="gripper_right_finger_base" class="collision" mesh="gripper_lite_right_finger_wide_base" material="black" condim="1" solimp="2 1 0.01" solref="0.01 1" friction="5 0.5 0.1"/>
                      <geom name="gripper_right_finger" class="collision" mesh="gripper_lite_right_finger_wide_tip" material="black" condim="4" solimp="2 1 0.01" solref="0.01 1" friction="5 0.5 0.1"/>
                    </body>
                    <!-- End effector reference point is in the centre at the tip of the grippers -->
                    <site name="end_effector" pos="0 0 0.0811" size="0.001 0.001 0.001" rgba="0.5 0.5 0.5 0.2"/>
                  </body>
                </body>
              </body>
            </body>
          </body>
        </body>
      </body>
    </body>

    <!-- Scene objects for visualisation -->
    <!-- <light pos="0 0 1.5" dir="0 0 -1" directional="true"/>
    <geom name="floor" size="0 0 0.05" type="plane" material="groundplane"/> -->

    <!-- Free floating target body to visualise target/goal pose, with rectangular prism ends for distinction-->
    <body name="target" pos=".3 .3 .3" quat="1 0 0 0" mocap="true">
      <site name="target" group="2"/>
      <!-- <geom class="target" fromto=".07 0 0 .15 0 0" rgba="1 0 0 1"/>
      <geom class="target" fromto="0 .07 0 0 .15 0" rgba="0 1 0 1"/>
      <geom class="target" fromto="0 0 .07 0 0 .15" rgba="0 0 1 1"/> -->
    </body>
  </worldbody>

  <actuator>
    <position joint="joint1" group="1" class="size1" kp="2000" kv="600" ctrlrange="-6.28319 6.28319" />
    <position joint="joint2" group="1" class="size1" kp="2000" kv="600" ctrlrange="-2.61799 2.61799" />
    <position joint="joint3" group="1" class="size2" kp="2000" kv="600" ctrlrange="-0.061087 5.23599" />
    <position joint="joint4" group="1" class="size2" kp="2000" kv="600" ctrlrange="-6.28319 6.28319" />
    <position joint="joint5" group="1" class="size2" kp="2000" kv="600" ctrlrange="-2.1642 2.1642" />
    <position joint="joint6" group="1" class="size3" kp="2000" kv="600" ctrlrange="-6.28319 6.28319" />

    <velocity joint="joint1" group="2" class="size1" kv="600" ctrlrange="-4 4" />
    <velocity joint="joint2" group="2" class="size1" kv="600" ctrlrange="-4 4" />
    <velocity joint="joint3" group="2" class="size2" kv="600" ctrlrange="-4 4" />
    <velocity joint="joint4" group="2" class="size2" kv="600" ctrlrange="-4 4" />
    <velocity joint="joint5" group="2" class="size2" kv="600" ctrlrange="-4 4" />
    <velocity joint="joint6" group="2" class="size3" kv="600" ctrlrange="-4 4" />
    <!-- TODO: Should it also be halved due to doubling with the right finger? -->
    <motor name="gripper" joint="gripper_left_finger" group="0" forcerange="-10 10" ctrlrange="-10 10"/>
  </actuator>

  <equality>
    <joint joint1="gripper_left_finger" joint2="gripper_right_finger" polycoef="0 -1 0 0 0"/>
  </equality>

  <!-- Keep in mind this is a bit field so use powers of 2, i.e. 2**group_id -->
  <option actuatorgroupdisable="2" />

</mujoco>
